<?xml version="1.0"?>
<robot xmlns:xacro="[http://www.ros.org/wiki/xacro](http://www.ros.org/wiki/xacro)" name="suwi_rover">

  <xacro:include filename="inertia_macros.xacro" />
  <link name="base_link"></link>

  <!-- CHASSIS -->
  <link name="chassis">
    <visual>
      <origin xyz="0 0 0.1" rpy="0 0 0"/>
      <geometry><box size="0.4 0.2 0.1"/></geometry>
      <material name="blue"><color rgba="0 0 1 1"/></material>
    </visual>
    <collision>
      <origin xyz="0 0 0.1" rpy="0 0 0"/>
      <geometry><box size="0.4 0.2 0.1"/></geometry>
    </collision>
    <xacro:inertial_box mass="1.0" x="0.4" y="0.2" z="0.1">
      <origin xyz="0 0 0.1" rpy="0 0 0"/>
    </xacro:inertial_box>
  </link>
  <gazebo reference="chassis"><material>Gazebo/Blue</material></gazebo>

  <joint name="base_to_chassis" type="fixed">
    <parent link="base_link"/>
    <child link="chassis"/>
  </joint>

  <!-- CASTER WHEEL -->
  <link name="caster_wheel">
    <visual>
      <geometry><sphere radius="0.05"/></geometry>
      <material name="black"><color rgba="0 0 0 1"/></material>
    </visual>
    <collision><geometry><sphere radius="0.05"/></geometry></collision>
    <xacro:inertial_cylinder mass="0.1" length="0.1" radius="0.05">
      <origin xyz="0 0 0" rpy="0 0 0"/>
    </xacro:inertial_cylinder>
  </link>
  <gazebo reference="caster_wheel"><material>Gazebo/Black</material><mu1>0.0</mu1><mu2>0.0</mu2></gazebo>
  <joint name="chassis_to_caster" type="fixed"><parent link="chassis"/><child link="caster_wheel"/><origin xyz="-0.15 0 0.05"/></joint>

  <!-- DRIVE WHEELS -->
  <xacro:macro name="wheel" params="prefix y_offset">
    <link name="${prefix}_wheel">
      <visual>
        <origin xyz="0 0 0" rpy="1.57 0 0"/>
        <geometry><cylinder radius="0.1" length="0.05"/></geometry>
        <material name="red"><color rgba="1 0 0 1"/></material>
      </visual>
      <collision><origin xyz="0 0 0" rpy="1.57 0 0"/><geometry><cylinder radius="0.1" length="0.05"/></geometry></collision>
      <xacro:inertial_cylinder mass="0.2" length="0.05" radius="0.1"><origin xyz="0 0 0" rpy="1.57 0 0"/></xacro:inertial_cylinder>
    </link>
    <gazebo reference="${prefix}_wheel"><material>Gazebo/Red</material><mu1>1.0</mu1><mu2>1.0</mu2></gazebo>
    <joint name="chassis_to_${prefix}_wheel" type="continuous"><parent link="chassis"/><child link="${prefix}_wheel"/><origin xyz="0.1 ${y_offset} 0.1"/><axis xyz="0 1 0"/> </joint>
  </xacro:macro>
  <xacro:wheel prefix="left" y_offset="0.12" />
  <xacro:wheel prefix="right" y_offset="-0.12" />

  <!-- LIDAR SENSOR -->
  <link name="lidar_link">
    <visual><geometry><cylinder radius="0.05" length="0.04"/></geometry><material name="black"><color rgba="0 0 0 1"/></material></visual>
    <collision><geometry><cylinder radius="0.05" length="0.04"/></geometry></collision>
    <xacro:inertial_cylinder mass="0.1" length="0.04" radius="0.05"><origin xyz="0 0 0" rpy="0 0 0"/></xacro:inertial_cylinder>
  </link>
  <joint name="chassis_to_lidar" type="fixed"><parent link="chassis"/><child link="lidar_link"/><origin xyz="0 0 0.17"/></joint>
  
  <gazebo reference="lidar_link">
    <material>Gazebo/Black</material>
    <sensor type="ray" name="lidar_sensor">
      <pose>0 0 0 0 0 0</pose><visualize>true</visualize><update_rate>10</update_rate>
      <ray><scan><horizontal><samples>360</samples><resolution>1</resolution><min_angle>-3.14</min_angle><max_angle>3.14</max_angle></horizontal></scan><range><min>0.3</min><max>12.0</max></range></ray>
      <plugin name="laser_controller" filename="libgazebo_ros_ray_sensor.so"><ros><remapping>~/out:=scan</remapping></ros><output_type>sensor_msgs/LaserScan</output_type><frame_name>lidar_link</frame_name></plugin>
    </sensor>
  </gazebo>

  <!-- ========================================== -->
  <!-- NEW: CAMERA SENSOR                         -->
  <!-- ========================================== -->
  <link name="camera_link">
    <visual>
      <geometry><box size="0.02 0.05 0.05"/></geometry>
      <material name="black"><color rgba="0 0 0 1"/></material>
    </visual>
    <collision><geometry><box size="0.02 0.05 0.05"/></geometry></collision>
    <xacro:inertial_box mass="0.05" x="0.02" y="0.05" z="0.05"><origin xyz="0 0 0" rpy="0 0 0"/></xacro:inertial_box>
  </link>

  <joint name="chassis_to_camera" type="fixed">
    <parent link="chassis"/>
    <child link="camera_link"/>
    <!-- Mounted on the front of the chassis (x=0.2) -->
    <origin xyz="0.2 0 0.05"/>
  </joint>

  <!-- GAZEBO CAMERA PLUGIN -->
  <gazebo reference="camera_link">
    <sensor type="camera" name="front_camera">
      <update_rate>30.0</update_rate>
      <camera>
        <horizontal_fov>1.089</horizontal_fov>
        <image>
          <format>R8G8B8</format>
          <width>640</width>
          <height>480</height>
        </image>
        <clip>
          <near>0.05</near>
          <far>8.0</far>
        </clip>
      </camera>
      <plugin name="camera_controller" filename="libgazebo_ros_camera.so">
        <frame_name>camera_link</frame_name>
      </plugin>
    </sensor>
  </gazebo>

  <!-- MOTOR PLUGIN -->
  <gazebo>
    <plugin name="diff_drive" filename="libgazebo_ros_diff_drive.so">
      <left_joint>chassis_to_left_wheel</left_joint>
      <right_joint>chassis_to_right_wheel</right_joint>
      <wheel_separation>0.24</wheel_separation>
      <wheel_diameter>0.2</wheel_diameter>
      <max_wheel_torque>20</max_wheel_torque>
      <max_wheel_acceleration>1.0</max_wheel_acceleration>
      <command_topic>cmd_vel</command_topic>
      <publish_odom>true</publish_odom>
      <publish_odom_tf>true</publish_odom_tf>
      <publish_wheel_tf>true</publish_wheel_tf>
      <odometry_frame>odom</odometry_frame>
      <robot_base_frame>base_link</robot_base_frame>
    </plugin>
  </gazebo>

  <link name="imu_link">
    <visual>
      <geometry>
        <box size="0.05 0.05 0.05"/>
      </geometry>
      <material name="black"/>
    </visual>
  </link>

  <joint name="imu_joint" type="fixed">
    <parent link="chassis"/>
    <child link="imu_link"/>
    <origin xyz="0 0 0.1" rpy="0 0 0"/>
  </joint>

  <gazebo reference="imu_link">
    <sensor name="imu_sensor" type="imu">
      <plugin filename="libgazebo_ros_imu_sensor.so" name="imu_plugin">
        <ros>
          <namespace>/imu</namespace>
          <remapping>~/out:=data</remapping>
        </ros>
        <initial_orientation_as_reference>false</initial_orientation_as_reference>
      </plugin>
      <always_on>true</always_on>
      <update_rate>100</update_rate>
      <visualize>true</visualize>
    </sensor>
  </gazebo>

</robot>
